Watching for file changes with StatReloader
Performing system checks...

System check identified no issues (0 silenced).

You have 18 unapplied migration(s). Your project may not work properly until you apply the migrations for app(s): admin, auth, contenttypes, sessions.
Run 'python manage.py migrate' to apply them.
June 28, 2023 - 07:53:27
Django version 4.2.2, using settings 'work.settings'
Starting development server at http://0.0.0.0:8000/
Quit the server with CONTROL-C.

[28/Jun/2023 07:53:38] "GET /homework/uptime HTTP/1.1" 200 419
[28/Jun/2023 07:53:44] "GET /homework/uptime HTTP/1.1" 200 419
[28/Jun/2023 07:54:36] "GET /homework/uptime HTTP/1.1" 200 419
[28/Jun/2023 07:54:37] "GET /homework/uptime HTTP/1.1" 200 419
[28/Jun/2023 07:54:38] "GET /homework/uptime HTTP/1.1" 200 419
[28/Jun/2023 07:59:11] "GET /homework/uptime HTTP/1.1" 200 419
[28/Jun/2023 08:41:31,992] - Broken pipe from ('162.142.125.12', 41674)
Not Found: /
[28/Jun/2023 08:41:33] "GET / HTTP/1.1" 404 2171
[28/Jun/2023 08:41:33,419] - Broken pipe from ('162.142.125.12', 39948)
Not Found: /
[28/Jun/2023 08:41:33] "GET / HTTP/1.1" 404 2171
[28/Jun/2023 08:41:34] code 505, message Invalid HTTP version (2.0)
[28/Jun/2023 08:41:34] "PRI * HTTP/2.0" 505 -
/opt/work/homework/views.py changed, reloading.
Watching for file changes with StatReloader
Performing system checks...

Exception in thread django-main-thread:
Traceback (most recent call last):
  File "/usr/lib64/python3.9/threading.py", line 980, in _bootstrap_inner
    self.run()
  File "/usr/lib64/python3.9/threading.py", line 917, in run
    self._target(*self._args, **self._kwargs)
  File "/usr/local/lib/python3.9/site-packages/django/utils/autoreload.py", line 64, in wrapper
    fn(*args, **kwargs)
  File "/usr/local/lib/python3.9/site-packages/django/core/management/commands/runserver.py", line 133, in inner_run
    self.check(display_num_errors=True)
  File "/usr/local/lib/python3.9/site-packages/django/core/management/base.py", line 485, in check
    all_issues = checks.run_checks(
  File "/usr/local/lib/python3.9/site-packages/django/core/checks/registry.py", line 88, in run_checks
    new_errors = check(app_configs=app_configs, databases=databases)
  File "/usr/local/lib/python3.9/site-packages/django/core/checks/urls.py", line 14, in check_url_config
    return check_resolver(resolver)
  File "/usr/local/lib/python3.9/site-packages/django/core/checks/urls.py", line 24, in check_resolver
    return check_method()
  File "/usr/local/lib/python3.9/site-packages/django/urls/resolvers.py", line 494, in check
    for pattern in self.url_patterns:
  File "/usr/local/lib/python3.9/site-packages/django/utils/functional.py", line 57, in __get__
    res = instance.__dict__[self.name] = self.func(instance)
  File "/usr/local/lib/python3.9/site-packages/django/urls/resolvers.py", line 715, in url_patterns
    patterns = getattr(self.urlconf_module, "urlpatterns", self.urlconf_module)
  File "/usr/local/lib/python3.9/site-packages/django/utils/functional.py", line 57, in __get__
    res = instance.__dict__[self.name] = self.func(instance)
  File "/usr/local/lib/python3.9/site-packages/django/urls/resolvers.py", line 708, in urlconf_module
    return import_module(self.urlconf_name)
  File "/usr/lib64/python3.9/importlib/__init__.py", line 127, in import_module
    return _bootstrap._gcd_import(name[level:], package, level)
  File "<frozen importlib._bootstrap>", line 1030, in _gcd_import
  File "<frozen importlib._bootstrap>", line 1007, in _find_and_load
  File "<frozen importlib._bootstrap>", line 986, in _find_and_load_unlocked
  File "<frozen importlib._bootstrap>", line 680, in _load_unlocked
  File "<frozen importlib._bootstrap_external>", line 850, in exec_module
  File "<frozen importlib._bootstrap>", line 228, in _call_with_frames_removed
  File "/opt/work/work/urls.py", line 22, in <module>
    path("homework/", include("homework.urls"))
  File "/usr/local/lib/python3.9/site-packages/django/urls/conf.py", line 38, in include
    urlconf_module = import_module(urlconf_module)
  File "/usr/lib64/python3.9/importlib/__init__.py", line 127, in import_module
    return _bootstrap._gcd_import(name[level:], package, level)
  File "<frozen importlib._bootstrap>", line 1030, in _gcd_import
  File "<frozen importlib._bootstrap>", line 1007, in _find_and_load
  File "<frozen importlib._bootstrap>", line 986, in _find_and_load_unlocked
  File "<frozen importlib._bootstrap>", line 680, in _load_unlocked
  File "<frozen importlib._bootstrap_external>", line 850, in exec_module
  File "<frozen importlib._bootstrap>", line 228, in _call_with_frames_removed
  File "/opt/work/homework/urls.py", line 2, in <module>
    from . import views
  File "/opt/work/homework/views.py", line 17
    # Create your views here.
                             ^
SyntaxError: unexpected EOF while parsing
/opt/work/homework/views.py changed, reloading.
Watching for file changes with StatReloader
Performing system checks...

Exception in thread django-main-thread:
Traceback (most recent call last):
  File "/usr/lib64/python3.9/threading.py", line 980, in _bootstrap_inner
    self.run()
  File "/usr/lib64/python3.9/threading.py", line 917, in run
    self._target(*self._args, **self._kwargs)
  File "/usr/local/lib/python3.9/site-packages/django/utils/autoreload.py", line 64, in wrapper
    fn(*args, **kwargs)
  File "/usr/local/lib/python3.9/site-packages/django/core/management/commands/runserver.py", line 133, in inner_run
    self.check(display_num_errors=True)
  File "/usr/local/lib/python3.9/site-packages/django/core/management/base.py", line 485, in check
    all_issues = checks.run_checks(
  File "/usr/local/lib/python3.9/site-packages/django/core/checks/registry.py", line 88, in run_checks
    new_errors = check(app_configs=app_configs, databases=databases)
  File "/usr/local/lib/python3.9/site-packages/django/core/checks/urls.py", line 14, in check_url_config
    return check_resolver(resolver)
  File "/usr/local/lib/python3.9/site-packages/django/core/checks/urls.py", line 24, in check_resolver
    return check_method()
  File "/usr/local/lib/python3.9/site-packages/django/urls/resolvers.py", line 494, in check
    for pattern in self.url_patterns:
  File "/usr/local/lib/python3.9/site-packages/django/utils/functional.py", line 57, in __get__
    res = instance.__dict__[self.name] = self.func(instance)
  File "/usr/local/lib/python3.9/site-packages/django/urls/resolvers.py", line 715, in url_patterns
    patterns = getattr(self.urlconf_module, "urlpatterns", self.urlconf_module)
  File "/usr/local/lib/python3.9/site-packages/django/utils/functional.py", line 57, in __get__
    res = instance.__dict__[self.name] = self.func(instance)
  File "/usr/local/lib/python3.9/site-packages/django/urls/resolvers.py", line 708, in urlconf_module
    return import_module(self.urlconf_name)
  File "/usr/lib64/python3.9/importlib/__init__.py", line 127, in import_module
    return _bootstrap._gcd_import(name[level:], package, level)
  File "<frozen importlib._bootstrap>", line 1030, in _gcd_import
  File "<frozen importlib._bootstrap>", line 1007, in _find_and_load
  File "<frozen importlib._bootstrap>", line 986, in _find_and_load_unlocked
  File "<frozen importlib._bootstrap>", line 680, in _load_unlocked
  File "<frozen importlib._bootstrap_external>", line 850, in exec_module
  File "<frozen importlib._bootstrap>", line 228, in _call_with_frames_removed
  File "/opt/work/work/urls.py", line 22, in <module>
    path("homework/", include("homework.urls"))
  File "/usr/local/lib/python3.9/site-packages/django/urls/conf.py", line 38, in include
    urlconf_module = import_module(urlconf_module)
  File "/usr/lib64/python3.9/importlib/__init__.py", line 127, in import_module
    return _bootstrap._gcd_import(name[level:], package, level)
  File "<frozen importlib._bootstrap>", line 1030, in _gcd_import
  File "<frozen importlib._bootstrap>", line 1007, in _find_and_load
  File "<frozen importlib._bootstrap>", line 986, in _find_and_load_unlocked
  File "<frozen importlib._bootstrap>", line 680, in _load_unlocked
  File "<frozen importlib._bootstrap_external>", line 850, in exec_module
  File "<frozen importlib._bootstrap>", line 228, in _call_with_frames_removed
  File "/opt/work/homework/urls.py", line 2, in <module>
    from . import views
  File "/opt/work/homework/views.py", line 18
    # Create your views here.
                             ^
SyntaxError: unexpected EOF while parsing
/opt/work/homework/views.py changed, reloading.
Watching for file changes with StatReloader
Performing system checks...

System check identified no issues (0 silenced).

You have 18 unapplied migration(s). Your project may not work properly until you apply the migrations for app(s): admin, auth, contenttypes, sessions.
Run 'python manage.py migrate' to apply them.
June 28, 2023 - 10:41:11
Django version 4.2.2, using settings 'work.settings'
Starting development server at http://0.0.0.0:8000/
Quit the server with CONTROL-C.

Internal Server Error: /homework/uptime
Traceback (most recent call last):
  File "/usr/local/lib/python3.9/site-packages/django/core/handlers/exception.py", line 55, in inner
    response = get_response(request)
  File "/usr/local/lib/python3.9/site-packages/django/core/handlers/base.py", line 197, in _get_response
    response = wrapped_callback(request, *callback_args, **callback_kwargs)
  File "/opt/work/homework/views.py", line 13, in print_linux_uptime
    template = loader.get_template("home.html")
  File "/usr/local/lib/python3.9/site-packages/django/template/loader.py", line 19, in get_template
    raise TemplateDoesNotExist(template_name, chain=chain)
django.template.exceptions.TemplateDoesNotExist: home.html
[28/Jun/2023 10:42:13] "GET /homework/uptime HTTP/1.1" 500 64278
Watching for file changes with StatReloader
Performing system checks...

System check identified no issues (0 silenced).

You have 18 unapplied migration(s). Your project may not work properly until you apply the migrations for app(s): admin, auth, contenttypes, sessions.
Run 'python manage.py migrate' to apply them.
June 28, 2023 - 14:40:27
Django version 4.2.2, using settings 'work.settings'
Starting development server at http://0.0.0.0:8000/
Quit the server with CONTROL-C.

Internal Server Error: /homework/uptime
Traceback (most recent call last):
  File "/usr/local/lib/python3.9/site-packages/django/core/handlers/exception.py", line 55, in inner
    response = get_response(request)
  File "/usr/local/lib/python3.9/site-packages/django/core/handlers/base.py", line 197, in _get_response
    response = wrapped_callback(request, *callback_args, **callback_kwargs)
  File "/opt/work/homework/views.py", line 23, in print_linux_uptime
    return HttpResponse(template.render(context, request))
  File "/usr/local/lib/python3.9/site-packages/django/template/backends/django.py", line 61, in render
    return self.template.render(context)
  File "/usr/local/lib/python3.9/site-packages/django/template/base.py", line 175, in render
    return self._render(context)
  File "/usr/local/lib/python3.9/site-packages/django/template/base.py", line 167, in _render
    return self.nodelist.render(context)
  File "/usr/local/lib/python3.9/site-packages/django/template/base.py", line 1005, in render
    return SafeString("".join([node.render_annotated(context) for node in self]))
  File "/usr/local/lib/python3.9/site-packages/django/template/base.py", line 1005, in <listcomp>
    return SafeString("".join([node.render_annotated(context) for node in self]))
  File "/usr/local/lib/python3.9/site-packages/django/template/base.py", line 966, in render_annotated
    return self.render(context)
  File "/usr/local/lib/python3.9/site-packages/django/template/defaulttags.py", line 471, in render
    url = reverse(view_name, args=args, kwargs=kwargs, current_app=current_app)
  File "/usr/local/lib/python3.9/site-packages/django/urls/base.py", line 88, in reverse
    return resolver._reverse_with_prefix(view, prefix, *args, **kwargs)
  File "/usr/local/lib/python3.9/site-packages/django/urls/resolvers.py", line 828, in _reverse_with_prefix
    raise NoReverseMatch(msg)
django.urls.exceptions.NoReverseMatch: Reverse for 'process_input' not found. 'process_input' is not a valid view function or pattern name.
[28/Jun/2023 14:41:56] "GET /homework/uptime HTTP/1.1" 500 108191
[28/Jun/2023 14:43:42] "GET /homework/uptime HTTP/1.1" 200 919
[28/Jun/2023 14:43:50] "POST /homework/uptime HTTP/1.1" 200 919
/opt/work/homework/views.py changed, reloading.
Watching for file changes with StatReloader
Performing system checks...

System check identified no issues (0 silenced).

You have 18 unapplied migration(s). Your project may not work properly until you apply the migrations for app(s): admin, auth, contenttypes, sessions.
Run 'python manage.py migrate' to apply them.
June 28, 2023 - 14:46:54
Django version 4.2.2, using settings 'work.settings'
Starting development server at http://0.0.0.0:8000/
Quit the server with CONTROL-C.

/opt/work/homework/views.py changed, reloading.
Watching for file changes with StatReloader
Performing system checks...

System check identified no issues (0 silenced).

You have 18 unapplied migration(s). Your project may not work properly until you apply the migrations for app(s): admin, auth, contenttypes, sessions.
Run 'python manage.py migrate' to apply them.
June 28, 2023 - 14:48:37
Django version 4.2.2, using settings 'work.settings'
Starting development server at http://0.0.0.0:8000/
Quit the server with CONTROL-C.

Internal Server Error: /homework/uptime
Traceback (most recent call last):
  File "/usr/local/lib/python3.9/site-packages/django/core/handlers/exception.py", line 55, in inner
    response = get_response(request)
  File "/usr/local/lib/python3.9/site-packages/django/core/handlers/base.py", line 197, in _get_response
    response = wrapped_callback(request, *callback_args, **callback_kwargs)
  File "/opt/work/homework/views.py", line 17, in print_linux_uptime
    server = request.post.get(input_text)
AttributeError: 'WSGIRequest' object has no attribute 'post'
[28/Jun/2023 14:48:50] "POST /homework/uptime HTTP/1.1" 500 61241
/opt/work/homework/views.py changed, reloading.
Watching for file changes with StatReloader
Performing system checks...

System check identified no issues (0 silenced).

You have 18 unapplied migration(s). Your project may not work properly until you apply the migrations for app(s): admin, auth, contenttypes, sessions.
Run 'python manage.py migrate' to apply them.
June 28, 2023 - 14:49:52
Django version 4.2.2, using settings 'work.settings'
Starting development server at http://0.0.0.0:8000/
Quit the server with CONTROL-C.

Internal Server Error: /homework/uptime
Traceback (most recent call last):
  File "/usr/local/lib/python3.9/site-packages/django/core/handlers/exception.py", line 55, in inner
    response = get_response(request)
  File "/usr/local/lib/python3.9/site-packages/django/core/handlers/base.py", line 197, in _get_response
    response = wrapped_callback(request, *callback_args, **callback_kwargs)
  File "/opt/work/homework/views.py", line 17, in print_linux_uptime
    server = request.post.get("input_text")
AttributeError: 'WSGIRequest' object has no attribute 'post'
[28/Jun/2023 14:49:56] "POST /homework/uptime HTTP/1.1" 500 61265
/opt/work/homework/views.py changed, reloading.
Watching for file changes with StatReloader
Performing system checks...

System check identified no issues (0 silenced).

You have 18 unapplied migration(s). Your project may not work properly until you apply the migrations for app(s): admin, auth, contenttypes, sessions.
Run 'python manage.py migrate' to apply them.
June 28, 2023 - 14:52:26
Django version 4.2.2, using settings 'work.settings'
Starting development server at http://0.0.0.0:8000/
Quit the server with CONTROL-C.

[28/Jun/2023 14:52:32] "POST /homework/uptime HTTP/1.1" 200 926
[28/Jun/2023 14:52:38] "POST /homework/uptime HTTP/1.1" 200 926
[28/Jun/2023 14:52:56] "POST /homework/uptime HTTP/1.1" 200 926
[28/Jun/2023 14:53:06] "POST /homework/uptime HTTP/1.1" 200 926
[28/Jun/2023 14:53:17] "POST /homework/uptime HTTP/1.1" 200 925
[28/Jun/2023 14:58:14] "POST /homework/uptime HTTP/1.1" 200 925
/opt/work/homework/views.py changed, reloading.
Watching for file changes with StatReloader
Performing system checks...

System check identified no issues (0 silenced).

You have 18 unapplied migration(s). Your project may not work properly until you apply the migrations for app(s): admin, auth, contenttypes, sessions.
Run 'python manage.py migrate' to apply them.
June 28, 2023 - 15:11:28
Django version 4.2.2, using settings 'work.settings'
Starting development server at http://0.0.0.0:8000/
Quit the server with CONTROL-C.

[28/Jun/2023 16:09:30] "POST /homework/uptime HTTP/1.1" 200 925
/opt/work/homework/views.py changed, reloading.
Watching for file changes with StatReloader
Performing system checks...

System check identified no issues (0 silenced).

You have 18 unapplied migration(s). Your project may not work properly until you apply the migrations for app(s): admin, auth, contenttypes, sessions.
Run 'python manage.py migrate' to apply them.
June 28, 2023 - 16:15:19
Django version 4.2.2, using settings 'work.settings'
Starting development server at http://0.0.0.0:8000/
Quit the server with CONTROL-C.

/opt/work/homework/views.py changed, reloading.
Watching for file changes with StatReloader
Performing system checks...

System check identified no issues (0 silenced).

You have 18 unapplied migration(s). Your project may not work properly until you apply the migrations for app(s): admin, auth, contenttypes, sessions.
Run 'python manage.py migrate' to apply them.
June 28, 2023 - 16:37:30
Django version 4.2.2, using settings 'work.settings'
Starting development server at http://0.0.0.0:8000/
Quit the server with CONTROL-C.

